Workbook

Sheet Assumptions
B1: Sold Direct — Model Assumptions (Prime · 1% fee · AI-lean · bank sponsor)
B2: Amber = editable input. Grey = calculated. Every other tab links here.
B4: GLOBAL INPUTS
B5: Bond origination referral (% of bond, via ooba — Y1 only) | C5: 0.005
B6: Facilitation fee — non-partner deals (% of price) | C6: 0.01
B7: Gross margin (derived from COGS Build, blended) | C7: =1-SUM('COGS Build'!C20:G20)/SUM('COGS Build'!C22:G22)
B8: ZAR per USD | C8: 18.5
B9: Valuation multiple — low (x revenue) | C9: 4
B10: Valuation multiple — high (x revenue) | C10: 6
B11: Working-capital / contingency buffer (R) | C11: 3000000
B13: PER-YEAR REVENUE DRIVERS (BASE)
C14: Y1 | D14: Y2 | E14: Y3 | F14: Y4 | G14: Y5
B15: Avg transacting price (R) | C15: 6500000 | D15: 5750000 | E15: 5000000 | F15: 4500000 | G15: 4000000
B16: Bonded share (qualifying >=80% bond, any bank) | C16: 0.4 | D16: 0.4 | E16: 0.4 | F16: 0.42 | G16: 0.42
B17: Bond size = 90% of price (R) | C17: =C15*0.9 | D17: =D15*0.9 | E17: =E15*0.9 | F17: =F15*0.9 | G17: =G15*0.9
B18: Origination income / qualifying deal (R) (Y1 ooba → Y2+ in-house) | C18: =C17*C67 | D18: =D17*D67 | E18: =E17*E67 | F18: =F17*F67 | G18: =G17*G67
B19: Facilitation fee / non-partner deal (R) | C19: =C15*$C$6 | D19: =D15*$C$6 | E19: =E15*$C$6 | F19: =F15*$C$6 | G19: =G15*$C$6
B20: Referral OR fee / deal, blended (R) | C20: =C16*C18+(1-C16)*C19 | D20: =D16*D18+(1-D16)*D19 | E20: =E16*E18+(1-E16)*E19 | F20: =F16*F18+(1-F16)*F19 | G20: =G16*G18+(1-G16)*G19
B21: Conveyancing referral / deal (R) | C21: 9000 | D21: 9000 | E21: 9500 | F21: 10000 | G21: 10000
B22: Add-ons / deal (R) | C22: 5000 | D22: 5000 | E22: 5500 | F22: 6000 | G22: 6500
B23: Revenue per deal (R) | C23: =C20+C21+C22 | D23: =D20+D21+D22 | E23: =E20+E21+E22 | F23: =F20+F21+F22 | G23: =G20+G21+G22
B25: OTHER REVENUE
C26: Y1 | D26: Y2 | E26: Y3 | F26: Y4 | G26: Y5
B27: Bank headline sponsorship (R/yr) | C27: 3000000 | D27: 4000000 | E27: 5000000 | F27: 6500000 | G27: 8000000
B29: REGISTERED DEALS BY SCENARIO (reinvest-for-growth)
C30: Y1 | D30: Y2 | E30: Y3 | F30: Y4 | G30: Y5
B31: Conservative | C31: 30 | D31: 130 | E31: 400 | F31: 950 | G31: 1900
B32: Base | C32: 50 | D32: 220 | E32: 650 | F32: 1500 | G32: 2900
B33: Aggressive | C33: 80 | D33: 350 | E33: 1000 | F33: 2400 | G33: 4800
B35: REVENUE/DEAL MULTIPLIER BY SCENARIO
B36: Conservative | C36: 0.92
B37: Base | C37: 1
B38: Aggressive | C38: 1.1
B40: OPERATING EXPENSE INPUTS (BASE)
C41: Y1 | D41: Y2 | E41: Y3 | F41: Y4 | G41: Y5
B42: Total headcount (workers) | C42: 8 | D42: 14 | E42: 22 | F42: 34 | G42: 48
B43: AI-agent share of headcount | C43: 0.5 | D43: 0.5 | E43: 0.5 | F43: 0.5 | G43: 0.5
B44: Human FTEs | C44: =C42*(1-C43) | D44: =D42*(1-D43) | E44: =E42*(1-E43) | F44: =F42*(1-F43) | G44: =G42*(1-G43)
B45: AI agents | C45: =C42*C43 | D45: =D42*D43 | E45: =E42*E43 | F45: =F42*F43 | G45: =G42*G43
B46: Human fully-loaded cost / FTE (R/yr) | C46: 700000 | D46: 722000 | E46: 738000 | F46: 761000 | G46: 779000
...

Sheet P&L (Base)
B1: Base Case P&L (R unless noted)
C3: Y1 | D3: Y2 | E3: Y3 | F3: Y4 | G3: Y5
B4: Registered deals | C4: =Assumptions!C32 | D4: =Assumptions!D32 | E4: =Assumptions!E32 | F4: =Assumptions!F32 | G4: =Assumptions!G32
B5: Revenue per deal (R, incl. ancillary if on) | C5: =Assumptions!C23*Assumptions!$C$37+Assumptions!$C$63 | D5: =Assumptions!D23*Assumptions!$C$37+Assumptions!$C$63 | E5: =Assumptions!E23*Assumptions!$C$37+Assumptions!$C$63 | F5: =Assumptions!F23*Assumptions!$C$37+Assumptions!$C$63 | G5: =Assumptions!G23*Assumptions!$C$37+Assumptions!$C$63
B6: Transactional revenue | C6: =C4*C5 | D6: =D4*D5 | E6: =E4*E5 | F6: =F4*F5 | G6: =G4*G5
B7: Bank sponsorship | C7: =Assumptions!C27 | D7: =Assumptions!D27 | E7: =Assumptions!E27 | F7: =Assumptions!F27 | G7: =Assumptions!G27
B8: Total revenue | C8: =C6+C7 | D8: =D6+D7 | E8: =E6+E7 | F8: =F6+F7 | G8: =G6+G7
B9: COGS | C9: =-C8*(1-Assumptions!$C$7) | D9: =-D8*(1-Assumptions!$C$7) | E9: =-E8*(1-Assumptions!$C$7) | F9: =-F8*(1-Assumptions!$C$7) | G9: =-G8*(1-Assumptions!$C$7)
B10: Gross profit | C10: =C8*Assumptions!$C$7 | D10: =D8*Assumptions!$C$7 | E10: =E8*Assumptions!$C$7 | F10: =F8*Assumptions!$C$7 | G10: =G8*Assumptions!$C$7
B11: Gross margin | C11: =IF(C8=0,"",C10/C8) | D11: =IF(D8=0,"",D10/D8) | E11: =IF(E8=0,"",E10/E8) | F11: =IF(F8=0,"",F10/F8) | G11: =IF(G8=0,"",G10/G8)
B12: Payroll + AI agents | C12: =Assumptions!C48 | D12: =Assumptions!D48 | E12: =Assumptions!E48 | F12: =Assumptions!F48 | G12: =Assumptions!G48
B13: Marketing | C13: =Assumptions!C49 | D13: =Assumptions!D49 | E13: =Assumptions!E49 | F13: =Assumptions!F49 | G13: =Assumptions!G49
B14: Tech & tools | C14: =Assumptions!C50 | D14: =Assumptions!D50 | E14: =Assumptions!E50 | F14: =Assumptions!F50 | G14: =Assumptions!G50
B15: Legal / compliance / insurance | C15: =Assumptions!C51 | D15: =Assumptions!D51 | E15: =Assumptions!E51 | F15: =Assumptions!F51 | G15: =Assumptions!G51
B16: G&A / office / other | C16: =Assumptions!C52 | D16: =Assumptions!D52 | E16: =Assumptions!E52 | F16: =Assumptions!F52 | G16: =Assumptions!G52
B17: Bond origination (in-house) | C17: =Assumptions!C72 | D17: =Assumptions!D72 | E17: =Assumptions!E72 | F17: =Assumptions!F72 | G17: =Assumptions!G72
B18: Total operating expenses | C18: =SUM(C12:C17) | D18: =SUM(D12:D17) | E18: =SUM(E12:E17) | F18: =SUM(F12:F17) | G18: =SUM(G12:G17)
B19: EBITDA | C19: =C10-C18 | D19: =D10-D18 | E19: =E10-E18 | F19: =F10-F18 | G19: =G10-G18
B20: EBITDA margin | C20: =IF(C8=0,"",C19/C8) | D20: =IF(D8=0,"",D19/D8) | E20: =IF(E8=0,"",E19/E8) | F20: =IF(F8=0,"",F19/F8) | G20: =IF(G8=0,"",G19/G8)
B21: Cumulative EBITDA (cash proxy) | C21: =C19 | D21: =C21+D19 | E21: =D21+E19 | F21: =E21+F19 | G21: =F21+G19

Sheet Scenarios
B1: Scenario Comparison (R)
B3: CONSERVATIVE
C4: Y1 | D4: Y2 | E4: Y3 | F4: Y4 | G4: Y5
B5: Revenue | C5: =Assumptions!C31*(Assumptions!C23*Assumptions!$C$36+Assumptions!$C$63)+Assumptions!C27 | D5: =Assumptions!D31*(Assumptions!D23*Assumptions!$C$36+Assumptions!$C$63)+Assumptions!D27 | E5: =Assumptions!E31*(Assumptions!E23*Assumptions!$C$36+Assumptions!$C$63)+Assumptions!E27 | F5: =Assumptions!F31*(Assumptions!F23*Assumptions!$C$36+Assumptions!$C$63)+Assumptions!F27 | G5: =Assumptions!G31*(Assumptions!G23*Assumptions!$C$36+Assumptions!$C$63)+Assumptions!G27
B6: Gross profit | C6: =C5*Assumptions!$C$7 | D6: =D5*Assumptions!$C$7 | E6: =E5*Assumptions!$C$7 | F6: =F5*Assumptions!$C$7 | G6: =G5*Assumptions!$C$7
B7: Operating expenses | C7: =Assumptions!C53*Assumptions!$C$56 | D7: =Assumptions!D53*Assumptions!$C$56 | E7: =Assumptions!E53*Assumptions!$C$56 | F7: =Assumptions!F53*Assumptions!$C$56 | G7: =Assumptions!G53*Assumptions!$C$56
B8: EBITDA | C8: =C6-C7 | D8: =D6-D7 | E8: =E6-E7 | F8: =F6-F7 | G8: =G6-G7
B9: Cumulative EBITDA | C9: =C8 | D9: =C9+D8 | E9: =D9+E8 | F9: =E9+F8 | G9: =F9+G8
B10: profit-year helper | C10: =IF(C8>0,C$60,99) | D10: =IF(D8>0,D$60,99) | E10: =IF(E8>0,E$60,99) | F10: =IF(F8>0,F$60,99) | G10: =IF(G8>0,G$60,99)
B13: BASE
C14: Y1 | D14: Y2 | E14: Y3 | F14: Y4 | G14: Y5
B15: Revenue | C15: =Assumptions!C32*(Assumptions!C23*Assumptions!$C$37+Assumptions!$C$63)+Assumptions!C27 | D15: =Assumptions!D32*(Assumptions!D23*Assumptions!$C$37+Assumptions!$C$63)+Assumptions!D27 | E15: =Assumptions!E32*(Assumptions!E23*Assumptions!$C$37+Assumptions!$C$63)+Assumptions!E27 | F15: =Assumptions!F32*(Assumptions!F23*Assumptions!$C$37+Assumptions!$C$63)+Assumptions!F27 | G15: =Assumptions!G32*(Assumptions!G23*Assumptions!$C$37+Assumptions!$C$63)+Assumptions!G27
B16: Gross profit | C16: =C15*Assumptions!$C$7 | D16: =D15*Assumptions!$C$7 | E16: =E15*Assumptions!$C$7 | F16: =F15*Assumptions!$C$7 | G16: =G15*Assumptions!$C$7
B17: Operating expenses | C17: =Assumptions!C53*Assumptions!$C$57 | D17: =Assumptions!D53*Assumptions!$C$57 | E17: =Assumptions!E53*Assumptions!$C$57 | F17: =Assumptions!F53*Assumptions!$C$57 | G17: =Assumptions!G53*Assumptions!$C$57
B18: EBITDA | C18: =C16-C17 | D18: =D16-D17 | E18: =E16-E17 | F18: =F16-F17 | G18: =G16-G17
B19: Cumulative EBITDA | C19: =C18 | D19: =C19+D18 | E19: =D19+E18 | F19: =E19+F18 | G19: =F19+G18
B20: profit-year helper | C20: =IF(C18>0,C$60,99) | D20: =IF(D18>0,D$60,99) | E20: =IF(E18>0,E$60,99) | F20: =IF(F18>0,F$60,99) | G20: =IF(G18>0,G$60,99)
B23: AGGRESSIVE
C24: Y1 | D24: Y2 | E24: Y3 | F24: Y4 | G24: Y5
B25: Revenue | C25: =Assumptions!C33*(Assumptions!C23*Assumptions!$C$38+Assumptions!$C$63)+Assumptions!C27 | D25: =Assumptions!D33*(Assumptions!D23*Assumptions!$C$38+Assumptions!$C$63)+Assumptions!D27 | E25: =Assumptions!E33*(Assumptions!E23*Assumptions!$C$38+Assumptions!$C$63)+Assumptions!E27 | F25: =Assumptions!F33*(Assumptions!F23*Assumptions!$C$38+Assumptions!$C$63)+Assumptions!F27 | G25: =Assumptions!G33*(Assumptions!G23*Assumptions!$C$38+Assumptions!$C$63)+Assumptions!G27
B26: Gross profit | C26: =C25*Assumptions!$C$7 | D26: =D25*Assumptions!$C$7 | E26: =E25*Assumptions!$C$7 | F26: =F25*Assumptions!$C$7 | G26: =G25*Assumptions!$C$7
B27: Operating expenses | C27: =Assumptions!C53*Assumptions!$C$58 | D27: =Assumptions!D53*Assumptions!$C$58 | E27: =Assumptions!E53*Assumptions!$C$58 | F27: =Assumptions!F53*Assumptions!$C$58 | G27: =Assumptions!G53*Assumptions!$C$58
B28: EBITDA | C28: =C26-C27 | D28: =D26-D27 | E28: =E26-E27 | F28: =F26-F27 | G28: =G26-G27
B29: Cumulative EBITDA | C29: =C28 | D29: =C29+D28 | E29: =D29+E28 | F29: =E29+F28 | G29: =F29+G28
B30: profit-year helper | C30: =IF(C28>0,C$60,99) | D30: =IF(D28>0,D$60,99) | E30: =IF(E28>0,E$60,99) | F30: =IF(F28>0,F$60,99) | G30: =IF(G28>0,G$60,99)
B34: SUMMARY
C35: Conservative | D35: Base | E35: Aggressive
B36: Y5 revenue | C36: =G5 | D36: =G15 | E36: =G25
B37: Y5 EBITDA | C37: =G8 | D37: =G18 | E37: =G28
B38: Y5 EBITDA margin | C38: =IF(G5=0,"",G8/G5) | D38: =IF(G15=0,"",G18/G15) | E38: =IF(G25=0,"",G28/G25)
B39: Cumulative cash low-point | C39: =MIN(C9:G9) | D39: =MIN(C19:G19) | E39: =MIN(C29:G29)
B40: Capital need incl. buffer | C40: =-MIN(C9:G9)+Assumptions!$C$11 | D40: =-MIN(C19:G19)+Assumptions!$C$11 | E40: =-MIN(C29:G29)+Assumptions!$C$11
B41: First EBITDA-positive year | C41: ="Y"&MIN(C10:G10) | D41: ="Y"&MIN(C20:G20) | E41: ="Y"&MIN(C30:G30)
C60: 1 | D60: 2 | E60: 3 | F60: 4 | G60: 5

Sheet COGS Build
B1: COGS Build — bottom-up cost of delivering a deal
B2: Amber = editable input. Grey = calculated. The blended COGS here feeds the derived gross margin on Assumptions!C7.
B4: PER-DEAL DIRECT COSTS (R) | C4: Y1 | D4: Y2 | E4: Y3 | F4: Y4 | G4: Y5
B5: Platform & messaging (WhatsApp/BSP, funnel-loaded) | C5: 400 | D5: 370 | E5: 340 | F5: 320 | G5: 300
B6: FICA / KYC / AML + affordability checks | C6: 250 | D6: 240 | E6: 230 | F6: 225 | G6: 220
B7: E-signature & digital documents | C7: 180 | D7: 170 | E7: 160 | F7: 155 | G7: 150
B8: Property data / AVM / deeds / CMA | C8: 300 | D8: 285 | E8: 270 | F8: 260 | G8: 250
B9: Listing media & portal syndication (amortised incl. unsold) | C9: 3600 | D9: 3400 | E9: 3200 | F9: 3050 | G9: 2900
B10: Add-on / compliance-cert fulfilment (resold services) | C10: 3900 | D10: 3800 | E10: 3700 | F10: 3600 | G10: 3500
B11: Other / contingency & per-deal SaaS | C11: 600 | D11: 570 | E11: 540 | F11: 520 | G11: 500
B12: COGS per deal (R) | C12: =SUM(C5:C11) | D12: =SUM(D5:D11) | E12: =SUM(E5:E11) | F12: =SUM(F5:F11) | G12: =SUM(G5:G11)
B14: BUILD-UP TO TOTAL COGS | C14: Y1 | D14: Y2 | E14: Y3 | F14: Y4 | G14: Y5
B15: Registered deals (base) | C15: =Assumptions!C32 | D15: =Assumptions!D32 | E15: =Assumptions!E32 | F15: =Assumptions!F32 | G15: =Assumptions!G32
B16: Deal-driven COGS (R) | C16: =C12*C15 | D16: =D12*D15 | E16: =E12*E15 | F16: =F12*F15 | G16: =G12*G15
B17: Transactional revenue — base (R) | C17: =Assumptions!C23*C15 | D17: =Assumptions!D23*D15 | E17: =Assumptions!E23*E15 | F17: =Assumptions!F23*F15 | G17: =Assumptions!G23*G15
B18: Payment processing & risk (% of transactional) | C18: 0.007 | D18: 0.007 | E18: 0.007 | F18: 0.007 | G18: 0.007
B19: Processing & risk cost (R) | C19: =C17*C18 | D19: =D17*D18 | E19: =E17*E18 | F19: =F17*F18 | G19: =G17*G18
B20: TOTAL COGS (R) | C20: =C16+C19 | D20: =D16+D19 | E20: =E16+E19 | F20: =F16+F19 | G20: =G16+G19
B21: Bank sponsorship (R, 0 COGS) | C21: =Assumptions!C27 | D21: =Assumptions!D27 | E21: =Assumptions!E27 | F21: =Assumptions!F27 | G21: =Assumptions!G27
B22: Total revenue — base (R) | C22: =C17+C21 | D22: =D17+D21 | E22: =E17+E21 | F22: =F17+F21 | G22: =G17+G21
B23: COGS as % of revenue | C23: =IF(C22=0,"",C20/C22) | D23: =IF(D22=0,"",D20/D22) | E23: =IF(E22=0,"",E20/E22) | F23: =IF(F22=0,"",F20/F22) | G23: =IF(G22=0,"",G20/G22)
B25: Blended COGS % (5-yr) | C25: =SUM(C20:G20)/SUM(C22:G22)
B26: Implied blended gross margin | C26: =1-C25
B28: Excludes: in-house bond-origination consultant cost (own opex line) and the concierge team (payroll). Media & add-on fulfilment are the largest lines — validate vs supplier quotes (photographer, CoC inspectors, Property24/Private Property, BSP).

Sheet Market Sizing
B1: Market Sizing — TAM / SAM / SOM (linked to projection)
B2: Amber = input. Grey = calculated/linked. Estimates — see docs/dataroom/03-market-sizing.md for sources & reliability.
B4: HEADLINE (annual revenue pool)
B6: TAM — all SA residential transfers | C6: =C20
B7: SAM — upper-market (>~R4m), national | C7: =C27
B8: SOM — our base-case Y5 revenue | C8: =D32
B10: 1. THE MARKET CONTEXT (full-service commission pool)
B11: SA annual residential transfers | C11: 250000 | D11: ~207k-277k (Lightstone 2024)
B12: Avg transaction price - national (R) | C12: 1400000 | D12: Lightstone Q1 2024
B13: Total annual transaction value (R) | C13: =C11*C12 | D13: ~R350bn
B14: Avg agent commission incl VAT (%) | C14: 0.069 | D14: 6% x 1.15 VAT
B15: Agent commission pool / yr (R) | C15: =C13*C14 | D15: ~R24bn - what sellers pay for full service (context for the private-sale segment we serve)
B17: 2. TAM - addressable revenue pool (all SA transfers)
B18: SA transfers / yr | C18: =C11
B19: Our blended revenue / deal - national (R) | C19: 25000 | D19: 1% fee/referral + conveyancing + ecosystem, ~R1.4m home
B20: TAM revenue pool / yr (R) | C20: =C18*C19 | D20: ~R6.3bn
B22: 3. SAM - serviceable: UPPER-MARKET (>~R4m), national
B23: Upper-market (>~R4m) transfers / yr | C23: 35000 | D23: ESTIMATE — broadens as avg price tapers; confirm
B24: Avg prime transacting price (R) | C24: =Assumptions!C15 | D24: linked to model price
B25: Prime transaction value / yr (R) | C25: =C23*C24 | D25: ~R91bn
B26: Our revenue / deal - prime (R) | C26: =Assumptions!G23 | D26: linked to model Y5 rev/deal
B27: SAM revenue pool / yr (R) | C27: =C23*C26 | D27: ~R0.98bn
B29: 4. SOM - obtainable (our projection, linked)
C30: Conservative | D30: Base | E30: Aggressive
B31: Y5 registered deals | C31: =Assumptions!G31 | D31: =Assumptions!G32 | E31: =Assumptions!G33
B32: Y5 revenue (R) | C32: =Scenarios!C36 | D32: =Scenarios!D36 | E32: =Scenarios!E36
B33: SOM = % of upper-market transactions | C33: =C31/$C$23 | D33: =D31/$C$23 | E33: =E31/$C$23
B34: SOM = % of prime revenue pool | C34: =C32/$C$27 | D34: =D32/$C$27 | E34: =E32/$C$27
B35: For reference: % of ALL SA transfers | C35: =C31/$C$11 | D35: =D31/$C$11 | E35: =E31/$C$11
B37: 5. STRESS TEST / reality check
B38: Base implies this share of the upper-market by Y5 | C38: =D33
B39: Implied prime share moves inversely with the prime-pool estimate:
B40: If pool = 25,000 -> base Y5 share | C40: =D31/25000
B41: If pool = 35,000 (base) -> base Y5 share | C41: =D31/35000
B42: If pool = 50,000 -> base Y5 share | C42: =D31/50000
B44: POSITIONING: tapering price broadens the addressable pool, cutting the implied share from ~21% (prime-only) to ~8%.
B45: Land at prime (biggest rand savings + bond), expand down to upper-mid as the brand scales. As % of ALL SA transfers: ~1.2%.
B47: 6. CONSUMER VALUE - KEPT VS FULL-SERVICE BENCHMARK (sellers who choose self-service)
C48: Y1 | D48: Y2 | E48: Y3 | F48: Y4 | G48: Y5
B49: Avg sale price (R) | C49: =Assumptions!C15 | D49: =Assumptions!D15 | E49: =Assumptions!E15 | F49: =Assumptions!F15 | G49: =Assumptions!G15
...

Sheet Capital & Valuation
B1: Capital Requirement & Valuation
B3: CAPITAL (from Scenarios)
C4: Conservative | D4: Base | E4: Aggressive
B5: Total capital to breakeven (R) | C5: =Scenarios!C40 | D5: =Scenarios!D40 | E5: =Scenarios!E40
B6: in USD (approx) | C6: =C5/Assumptions!$C$8 | D6: =D5/Assumptions!$C$8 | E6: =E5/Assumptions!$C$8
B8: RECOMMENDED RAISE
B9: Seed round (R) — growth buffer above need | C9: 15000000
B10: Seed round (USD approx) | C10: =C9/Assumptions!$C$8
B12: VALUATION — REVENUE MULTIPLE (Base, Y5)
C13: Low | D13: High
B14: Y5 revenue (R) | C14: =Scenarios!D36 | D14: =Scenarios!D36
B15: Revenue multiple | C15: =Assumptions!C9 | D15: =Assumptions!C10
B16: Enterprise value (R) | C16: =C14*C15 | D16: =D14*D15
B17: Enterprise value (USD) | C17: =C16/Assumptions!$C$8 | D17: =D16/Assumptions!$C$8
B19: SEED ROUND FRAMING (illustrative)
B20: Seed pre-money (R) | C20: 50000000
B21: Seed raise (R) | C21: =C9
B22: Seed post-money (R) | C22: =C20+C21
B23: New-investor stake | C23: =C21/C22
B25: AGGRESSIVE UPSIDE
B26: Y5 revenue (R) | C26: =Scenarios!E36
B27: EV @ 5x (R) | C27: =C26*5

Sheet Use of Funds
B1: Use of Funds — seed round
B2: Amber = editable allocation. % and totals calculated. Seed amount linked from Capital & Valuation!C9.
B4: Category | C4: Amount (R) | D4: % | E4: What it buys / milestone
B5: Above-the-line / brand marketing | C5: 5000000 | D5: =C5/$C$11 | E5: First brand campaign in prime CT — the deal-ramp engine; prove ATL→deals conversion
B6: Team (AI-augmented, ~8 people) | C6: 5000000 | D6: =C6/$C$11 | E6: Founders + small human core (product, ops/concierge, partnerships); 12–18mo runway
B7: Product & technology | C7: 2000000 | D7: =C7/$C$11 | E7: WhatsApp Cloud API/BSP, AI agents, deal tracker, dashboard, security
B8: Partnerships & go-to-market | C8: 1000000 | D8: =C8/$C$11 | E8: ooba + panel conveyancers live; secure the bank headline sponsor; onboarding
B9: Legal / compliance / licensing | C9: 1000000 | D9: =C9/$C$11 | E9: PPRA practitioner + FFC, POPIA programme, contracts, mandate templates
B10: Working capital / contingency | C10: 1000000 | D10: =C10/$C$11 | E10: Buffer above the ~R6m modelled cash low-point
B11: Total allocated | C11: =SUM(C5:C10) | D11: =C11/$C$11
B12: Seed raise (linked) | C12: ='Capital & Valuation'!C9
B13: Check (allocated − seed; should be 0) | C13: =C11-C12
B15: Note: survival need is only ~R6m; the rest is growth capital (brand + team) to drive the deal ramp.

Sheet Cap Table
B1: Cap Table — ownership & dilution
B2: Founders 4 x 25%. Amber = editable round inputs; seed linked from Capital & Valuation.
B4: ROUND INPUTS
B5: Seed pre-money (R) | C5: ='Capital & Valuation'!C20
B6: Seed raise (R) | C6: ='Capital & Valuation'!C9
B7: Seed post-money (R) | C7: =C5+C6
B8: Series A pre-money (R) | C8: 250000000
B9: Series A raise (R) | C9: 50000000
B10: Series A post-money (R) | C10: =C8+C9
B11: Exit multiple (x Y5 revenue) | C11: 5
B12: Exit enterprise value — base Y5 (R) | C12: =Scenarios!D36*C11
B14: OWNERSHIP (%)
B15: Holder | C15: Founding | D15: Post-Seed | E15: Post-Series A
B16: Johannes — Commercial Director | C16: 0.25 | D16: =C16*($C$5/$C$7) | E16: =D16*($C$8/$C$10)
B17: Wilhelm — CTO | C17: 0.25 | D17: =C17*($C$5/$C$7) | E17: =D17*($C$8/$C$10)
B18: Dean — COO | C18: 0.25 | D18: =C18*($C$5/$C$7) | E18: =D18*($C$8/$C$10)
B19: Strategic Funder | C19: 0.25 | D19: =C19*($C$5/$C$7) | E19: =D19*($C$8/$C$10)
B20: Seed Investor | C20: 0 | D20: =$C$6/$C$7 | E20: =D20*($C$8/$C$10)
B21: Series A Investor | C21: 0 | D21: 0 | E21: =$C$9/$C$10
B22: Total | C22: =SUM(C16:C21) | D22: =SUM(D16:D21) | E22: =SUM(E16:E21)
B24: VALUE OF STAKE (R)
B25: Holder | C25: At Seed (R65m) | D25: At Series A | E25: At Exit
B26: Johannes — Commercial Director | C26: =D16*$C$7 | D26: =E16*$C$10 | E26: =E16*$C$12
B27: Wilhelm — CTO | C27: =D17*$C$7 | D27: =E17*$C$10 | E27: =E17*$C$12
B28: Dean — COO | C28: =D18*$C$7 | D28: =E18*$C$10 | E28: =E18*$C$12
B29: Strategic Funder | C29: =D19*$C$7 | D29: =E19*$C$10 | E29: =E19*$C$12
B30: Seed Investor | C30: =D20*$C$7 | D30: =E20*$C$10 | E30: =E20*$C$12
B31: Series A Investor | C31: =D21*$C$7 | D31: =E21*$C$10 | E31: =E21*$C$12
B32: Total | C32: =SUM(C26:C31) | D32: =SUM(D26:D31) | E32: =SUM(E26:E31)

Sheet Funder Growth
B1: Funder Growth — value of each stake by round
B2: Value of each holder's equity at Seed, Series A and Exit (base Y5 EV). MoM = exit value / cash invested.
B4: Holder | C4: Invested (R) | D4: Value @ Seed | E4: Value @ Series A | F4: Value @ Exit | G4: Exit MoM
B5: Johannes — Commercial Director | C5: 0 | D5: ='Cap Table'!C26 | E5: ='Cap Table'!D26 | F5: ='Cap Table'!E26 | G5: sweat
B6: Wilhelm — CTO | C6: 0 | D6: ='Cap Table'!C27 | E6: ='Cap Table'!D27 | F6: ='Cap Table'!E27 | G6: sweat
B7: Dean — COO | C7: 0 | D7: ='Cap Table'!C28 | E7: ='Cap Table'!D28 | F7: ='Cap Table'!E28 | G7: sweat
B8: Strategic Funder | C8: 0 | D8: ='Cap Table'!C29 | E8: ='Cap Table'!D29 | F8: ='Cap Table'!E29 | G8: sweat
B9: Seed Investor | C9: ='Cap Table'!C6 | D9: ='Cap Table'!C30 | E9: ='Cap Table'!D30 | F9: ='Cap Table'!E30 | G9: =F9/C9
B10: Series A Investor | C10: ='Cap Table'!C9 | D10: ='Cap Table'!C31 | E10: ='Cap Table'!D31 | F10: ='Cap Table'!E31 | G10: =F10/C10
B12: Founders hold 25% each for sweat; the Strategic Funder is an existing 25% holder. Exit uses the base-case Y5 EV (editable on Cap Table).

Sheet Competitive Landscape
B1: Competitive Landscape
B2: Sold Direct is the only 0%-to-consumer player that monetises the financial ecosystem around the deal via WhatsApp.
B4: Player | C4: Model | D4: Cost to seller | E4: Channel | F4: Bond / finance | G4: Ecosystem revenue | H4: Segment / status
B5: Sold Direct | C5: 0% marketplace + concierge | D5: 0% (1% non-partner) | E5: WhatsApp-native | F5: Multi-bank origination referral (core) | G5: Yes — insurance, solar, moving, life cover… | H5: Prime first; launching
B6: Traditional agencies (Pam Golding, Seeff, RE/MAX, Rawson) | C6: Full-service agency | D6: 5–7% + VAT | E6: Agents + portals | F6: Refer to originators | G6: Limited (referrals) | H6: Full-service sellers; established, commission-funded
B7: Property24 | C7: Listings portal | D7: Portal fees (to agents) | E7: Web / app portal | F7: Bond calculators & leads | G7: Ad / lead revenue | H7: All; dominant portal (Prosus)
B8: Private Property | C8: Listings portal | D8: Listing / portal fees | E8: Web portal | F8: Bond referral | G8: Ad / lead revenue | H8: All; #2 portal
B9: PropertyFox | C9: Low-commission hybrid | D9: ~1.5% flat | E9: Online + agents | F9: — | G9: Limited | H9: Mid; struggled / sold — cautionary
B10: Leadhome | C10: Fixed-fee online agency | D10: Low fixed fee | E10: Online + agents | F10: — | G10: Limited | H10: Mid; wound down — cautionary
B11: ooba / BetterBond | C11: Bond originators | D11: Free to consumer | E11: Web / agents | F11: Core business | G11: — | H11: Bonded buyers — PARTNERS, not rivals
B12: Purplebricks (UK) | C12: Fixed-fee online agency | D12: Fixed fee | E12: Online | F12: — | G12: Limited | H12: Defunct: £240m IPO → £1 — CAC warning
B14: NOTE: Traditional agents serve the full-service segment - complementary, not a target. Sold Direct serves sellers who choose to sell privately, assisted by our own employed, registered practitioners (PPRA/FFC).

Sheet Risk Register
B1: Risk Register
B2: Likelihood (L) & Impact (I): 1=Low, 2=Med, 3=High. Severity = L×I (green ≤2, amber 3–4, red ≥6).
B4: Risk | C4: Category | D4: L | E4: I | F4: Sev | G4: Mitigation
B5: ATL marketing doesn't convert to deals (CAC blows out) | C5: Growth | D5: 2 | E5: 3 | F5: =D5*E5 | G5: Pilot ATL in CT before scaling; track CAC payback; throttle spend to cash
B6: Prime pool smaller / ~20% share too ambitious | C6: Market | D6: 2 | E6: 3 | F6: =D6*E6 | G6: Confirm prime-pool data; conservative case ≈14% share; widen to upper-mid segment
B7: Regulatory — PPRA/FFC; bond-steering; FAIS/FSP & NCA once originating in-house | C7: Regulatory | D7: 2 | E7: 3 | F7: =D7*E7 | G7: Registered practitioner + FFC; multi-bank (no steering); FSP accreditation before Y2 switch; legal sign-off before launch
B8: POPIA / data breach (IDs, payslips, bank data) | C8: Compliance | D8: 2 | E8: 3 | F8: =D8*E8 | G8: Encrypt at rest, minimise PII, consent logging, DPAs, security review (already in build)
B9: Trust/adoption — sellers wary of a new brand for R6m+ sale | C9: Adoption | D9: 2 | E9: 3 | F9: =D9*E9 | G9: Concierge model, panel conveyancers (funds in trust), testimonials, bank-sponsor halo
B10: Partner concentration (ooba, sponsor, conveyancers) | C10: Partner | D10: 2 | E10: 2 | F10: =D10*E10 | G10: Multi-bank via ooba; multiple conveyancers; non-exclusive sponsor
B11: Industry response (portals / agencies compete on price or copy features) | C11: Competitive | D11: 2 | E11: 2 | F11: =D11*E11 | G11: Position as complementary to full-service agents (private-sale segment only); we employ registered practitioners; no anti-agent marketing; speed + WhatsApp UX + ecosystem + data advantage
B12: AI agents underperform for high-touch prime clients | C12: Operational | D12: 2 | E12: 2 | F12: =D12*E12 | G12: Human-in-the-loop on prime; AI for coordination not advice; QA + escalation
B13: Property downturn / rates → fewer transactions | C13: Macro | D13: 2 | E13: 2 | F13: =D13*E13 | G13: Counter-cyclical 0% appeal; lean cost base; flex marketing spend
B14: WhatsApp / Meta platform & pricing dependency | C14: Platform | D14: 1 | E14: 2 | F14: =D14*E14 | G14: BSP-agnostic adapter (built); web fallback; monitor Meta pricing
B15: Key-person / small-team dependency | C15: Team | D15: 2 | E15: 2 | F15: =D15*E15 | G15: Document + cross-train; AI leverage; hire on the raise
B16: High-margin assumptions hurt the fundraise | C16: Funding | D16: 2 | E16: 2 | F16: =D16*E16 | G16: Lead with conservative case + traction; reinvest-for-growth framing
B17: In-house bond origination — bank aggregation agreements & FAIS/FSP accreditation (Y2) | C17: Regulatory/Partner | D17: 2 | E17: 3 | F17: =D17*E17 | G17: Y1 via ooba = runway; sign multi-bank aggregation pre-Y2; FSP accreditation; phase-in; ooba fallback if a bank agreement slips
B18: Top risks (Sev 6): marketing-conversion, prime-share, in-house-origination readiness, regulatory, POPIA, trust/adoption — each has an owner action above.

Sheet Ancillary Revenue
B1: Ancillary / Ecosystem Revenue — the value of the database
B2: Referral & commission streams unlocked by owning the homeowner relationship + data. Optional: toggle into the P&L on Assumptions!C61.
B4: Revenue stream | C4: Low (R) | D4: High (R) | E4: Midpoint (R) | F4: Attach % | G4: Captured/deal (R)
B5: Homeowners insurance commission | C5: 1500 | D5: 4000 | E5: =AVERAGE(C5:D5) | F5: 0.3 | G5: =E5*F5
B6: Household contents insurance | C6: 500 | D6: 2000 | E6: =AVERAGE(C6:D6) | F6: 0.25 | G6: =E6*F6
B7: Conveyancing referral/marketing fee (already in core) | C7: 3000 | D7: 8000 | E7: =AVERAGE(C7:D7) | F7: 0 | G7: =E7*F7
B8: Moving company referral | C8: 500 | D8: 2000 | E8: =AVERAGE(C8:D8) | F8: 0.2 | G8: =E8*F8
B9: Fibre / internet installation | C9: 500 | D9: 1500 | E9: =AVERAGE(C9:D9) | F9: 0.2 | G9: =E9*F9
B10: Security system installation | C10: 1000 | D10: 3000 | E10: =AVERAGE(C10:D10) | F10: 0.15 | G10: =E10*F10
B11: Utility connection service | C11: 250 | D11: 1000 | E11: =AVERAGE(C11:D11) | F11: 0.3 | G11: =E11*F11
B12: Home warranty / product upsell | C12: 500 | D12: 2500 | E12: =AVERAGE(C12:D12) | F12: 0.1 | G12: =E12*F12
B13: Compliance certificates (already in core add-ons) | C13: 500 | D13: 2000 | E13: =AVERAGE(C13:D13) | F13: 0 | G13: =E13*F13
B14: Solar installation referral | C14: 5000 | D14: 20000 | E14: =AVERAGE(C14:D14) | F14: 0.05 | G14: =E14*F14
B15: Home improvement / renovation referrals | C15: 2000 | D15: 15000 | E15: =AVERAGE(C15:D15) | F15: 0.08 | G15: =E15*F15
B16: Storage solutions referral | C16: 500 | D16: 2000 | E16: =AVERAGE(C16:D16) | F16: 0.1 | G16: =E16*F16
... B19: Estate planning / will services | C19: 500 | D19: 2000 | E19: =AVERAGE(C19:D19) | F19: 0.1 | G19: =E19*F19
B21: FULL ecosystem potential / customer (sum of midpoints) | E21: =SUM(E5:E19)
B22: Realistic ADDITIONAL captured / deal (sum of captured) | G22: =SUM(G5:G19)
B24: Conveyancing & compliance certs are already counted in the core model (attach set to 0 here to avoid double-counting).
B25: Strategic point: each registered customer is worth up to ~R50k of ecosystem referral revenue. Even ~10% capture ≈ R5k/deal — the database is the moat.

Sheet Notes & Sources
B1: Sold Direct — model notes & sources
B3: Strategy: prime / upper-market focus (Atlantic Seaboard, City Bowl, Southern Suburbs, Constantia; then prime JHB-north & Umhlanga).
B5: MONETISATION (legally clean - no bank exclusivity):
B6: • Free 0% requires a qualifying >=80% bond + our conveyancer; buyer keeps full rate choice. Y1: placed via our MULTI-BANK originator (ooba) — referral ~0.5% of bond. Y2+: origination goes IN-HOUSE, direct with the banks (full commission ~1.5% of bond, ~3x the referral) — needs bank aggregation agreements + FAIS/FSP accreditation; Y1 via ooba is the runway to secure them.
B7: • Otherwise a 1% facilitation fee on the price (cash / sub-80% / not using our partners) - ~6x less than a typical full-service commission (5-7% + VAT), stated as a neutral benchmark.
B8: • Bank HEADLINE SPONSORSHIP: a bank pays an annual fee to be the featured sponsor / brand on the platform (advertising, not steering) - high-margin, grows with audience.
B10: THE DATABASE / ECOSYSTEM (see Ancillary Revenue tab):
B11: • Owning the homeowner relationship unlocks a referral menu worth ~R50k of ecosystem revenue per customer (insurance, solar, moving, fibre, security, life cover, etc.).
B12: • Modelled conservatively as OPTIONAL: ~R5k additional captured per deal (~10% blended capture). Toggle into the P&L on Assumptions!C61 (default off).
B13: • This is the moat and the expansion-revenue story - default off keeps the headline P&L conservative; turning it on adds ~R14m to Y5 base revenue.
B15: AI-LEAN OPERATING MODEL:
B16: • 50% of headcount are AI agents (concierge/coordination/ops) at ~R0.15m/yr each vs ~R0.70-0.78m/yr fully-loaded human - roughly halves people-cost.
... B29: COGS (bottom-up): see the COGS Build tab — ~7 direct per-deal lines (messaging, FICA/KYC, e-sign, property data, listing media & portal syndication, add-on/compliance-cert fulfilment, contingency) + ~0.7% payment processing. Blends to ~12% of revenue (~88% gross margin, now DERIVED on Assumptions!C7). Excludes in-house origination cost (own line) and the concierge team (payroll).
